<mujoco>

	<visual>
			<headlight ambient="0.25 0.25 0.25"/>
	</visual>

	<option timestep="0.001" integrator="RK4" gravity="0 0 -9.81">
		<flag sensornoise="disable" contact="enable" energy="enable"/>
	</option>

	<worldbody>
		<geom type="plane" size="5 5 0.1" rgba=".9 0 0 1"/>

		<body name="pole" pos="0 0 2" euler="0 0 0">
			<joint name="x" type="slide" pos="0 0 0.5" axis = "1 0 0" />
			<joint name="z" type="slide" pos="0 0 0.5" axis = "0 0 1" />
			<joint name="pin" type="hinge" pos="0 0 0.5" axis="0 -1 0" />
			<geom type="cylinder" size=".05 .5" rgba="0 .9 0 1" mass="1"/>
		</body>

	</worldbody>

	<equality>
			<connect body1='pole' body2='world' anchor='0 0 0.5'/>
	</equality>

	<actuator>
		<position name="position_servo" joint="pin" kp="0"/>
		<velocity name="velocity_servo" joint="pin" kv="0"/>
	</actuator>


</mujoco>
